<?xml version="1.0" ?>
<robot name="megarover3" xmlns:xacro="http://ros.org/wiki/xacro">
  <xacro:include filename="$(find megarover_samples)/urdf/common.xacro"/>
  <xacro:include filename="$(find turtlebot3_description)/urdf/common_properties.xacro"/>
  <xacro:include filename="$(find potbot_example)/urdf/megarover3.gazebo.xacro"/>

  <xacro:property name="wheel_radius" value="0.076"/>
  <xacro:property name="wheel_length" value="0.03"/>
  <xacro:property name="wheel_mass" value="0.823"/>
  
  <link name="base_footprint"/>

  <joint name="base_joint" type="fixed">
    <parent link="base_footprint"/>
    <child link="base_link" />
    <origin xyz="-0.1 0 0" rpy="0 0 -1.5708" />
  </joint>

  <link name="base_link">
    <inertial>
      <origin xyz="-0.0001512201285105937 -3.420007213019073e-05 0.08388833658828038" rpy="0 0 0" />
      <mass value="11.744482" />
      <inertia ixx="0.091465" iyy="0.06435" izz="0.1253"
        ixy="0.001018" iyz="-0.002369"
        ixz="0.000233" />
    </inertial>
    <visual>
      <origin xyz="0 0 0" rpy="0 0 0" />
      <geometry>
        <mesh filename="package://megarover_description/meshes/mega3/base_link.stl" scale="0.001 0.001 0.001" />
      </geometry>
      <material name="silver" />
    </visual>
    <!-- <collision>
      <origin xyz="0 0 0" rpy="0 0 0"/>
      <geometry>
        <mesh filename="package://megarover_description/meshes/mega3/base_link.stl" scale="0.001 0.001 0.001"/>
      </geometry>
    </collision> -->
    <collision>
      <origin xyz="0 0 0.095" rpy="0 0 0" />
      <geometry>
        <box size="0.21 0.328 0.11" />
      </geometry>
    </collision>
    <collision>
      <origin xyz="0 -0.15 0.033" rpy="0 -1.57 0" />
      <geometry>
        <cylinder radius="0.0325" length="0.02" />
      </geometry>
    </collision>
  </link>

  <joint name="wheel_left_joint" type="continuous">
    <origin xyz="-0.136 0.1 0.07" rpy="0 -1.5708 0" />
    <parent link="base_link" />
    <child link="wheel_left_link" />
    <axis xyz="0 0 1" />
  </joint>

  <link name="wheel_left_link">
    <inertial>
      <origin xyz="0.0 0.0 0.00213" rpy="0 1.5708 0" />
      <mass value="1.239934" />
      <inertia ixx="0.002474" iyy="0.00174" izz="0.00174"
        ixy="0.000" iyz="0.000"
        ixz="-0.000" />
    </inertial>
    <visual>
      <origin xyz="-0.07 -0.1 -0.136" rpy="0 1.5708 0" />
      <geometry>
        <mesh filename="package://megarover_description/meshes/mega3/left_wheel_1.stl" scale="0.001 0.001 0.001" />
      </geometry>
      <material name="dark_grey" />
    </visual>
    <collision>
      <origin xyz="-0.07 -0.1 -0.136" rpy="0 1.5708 0" />
      <geometry>
        <mesh filename="package://megarover_description/meshes/mega3/left_wheel_1.stl" scale="0.001 0.001 0.001" />
      </geometry>
    </collision>
    <!-- <collision>
      <origin xyz="0 0 0" rpy="0 0 0" />
      <geometry>
        <cylinder radius="0.07" length="0.0435" />
      </geometry>
    </collision> -->
  </link>

  <joint name="wheel_right_joint" type="continuous">
    <origin xyz="0.136 0.1 0.07" rpy="0 -1.5708 0" />
    <parent link="base_link" />
    <child link="wheel_right_link" />
    <axis xyz="0 0 1" />
  </joint>

  <link name="wheel_right_link">
    <inertial>
      <origin xyz="0 0 -0.00213" rpy="0 1.5708 0" />
      <mass value="1.239934" />
      <inertia ixx="0.002474" iyy="0.00174" izz="0.00174"
        ixy="-0.000" iyz="-0.000"
        ixz="-0.000" />
    </inertial>
    <visual>
      <origin xyz="-0.07 -0.1 0.136" rpy="0 1.5708 0" />
      <geometry>
        <mesh filename="package://megarover_description/meshes/mega3/right_wheel_1.stl" scale="0.001 0.001 0.001" />
      </geometry>
      <material name="dark_grey" />
    </visual>
    <collision>
      <origin xyz="-0.07 -0.1 0.136" rpy="0 1.5708 0" />
      <geometry>
        <mesh filename="package://megarover_description/meshes/mega3/right_wheel_1.stl" scale="0.001 0.001 0.001" />
      </geometry>
    </collision>
    <!-- <collision>
      <origin xyz="0 0 0" rpy="0 0 0" />
      <geometry>
        <cylinder radius="0.07" length="0.0435" />
      </geometry>
    </collision> -->
  </link>

  <joint name="scan_joint" type="fixed">
    <parent link="base_link" />
    <child link="base_scan" />
    <origin xyz="0 0.18 0.223" rpy="0 0 1.57"/>
  </joint>

  <!-- <link name="base_scan">
    <visual>
      <origin xyz="0 0 -0.035" />
      <geometry>
        <cylinder length="0.07" radius="0.0175" />
      </geometry>
      <material name="grey" />
    </visual>
  </link> -->

  <link name="base_scan">
    <visual>
      <origin xyz="0 0 0" rpy="${M_PI} 0 0"/>
      <geometry>
        <mesh filename="package://megarover_samples/meshes/dae/lrf.dae"/>
      </geometry>
    </visual>
    <collision>
      <origin xyz="0 0 0" rpy="${M_PI} 0 0"/>
      <geometry>
        <mesh filename="package://megarover_samples/meshes/stl/lrf.stl"/>
      </geometry>
    </collision>
    <inertial>
      <origin xyz="0 0 0"/>
      <xacro:box_inertial mass="0.218" height="0.07" width="0.05" depth="0.05"/>
    </inertial>
  </link>

  <joint name="camera_stay_joint" type="fixed">
    <origin xyz="0 0.15 0.305" rpy="0 0 1.57"/>
    <parent link="base_link"/>
    <child link="camera_stay_link"/>
  </joint>

  <link name="camera_stay_link">
    <visual>
      <origin xyz="0 0 0" rpy="0 0 0"/>
      <geometry>
        <box size="0.02 0.02 0.3"/>
      </geometry>
      <material name="grey" />
    </visual>
    <collision>
      <origin xyz="0 0 0" rpy="0 0 0"/>
      <geometry>
        <box size="0.02 0.02 0.3"/>
      </geometry>
    </collision>
  </link>

  <joint name="camera_joint" type="fixed">
    <origin xyz="0 0 0.15" rpy="0 0 0"/>
    <parent link="camera_stay_link"/>
    <child link="camera_link"/>
  </joint>

  <link name="camera_link">
    <visual>
      <origin xyz="0 0 0" rpy="0 0 0"/>
      <geometry>
        <box size="0.03 0.165 0.03"/>
      </geometry>
      <material name="white" />
    </visual>
  </link>

  <joint name="imu_joint" type="fixed">
    <parent link="camera_link"/>
    <child link="imu_link"/>
    <!-- <origin xyz="0 0 0" rpy="3.14 0 0"/> -->
    <origin xyz="0 0 0" rpy="0 1.57 0"/>
  </joint>

  <link name="imu_link"/>

  <joint name="left_camera_joint" type="fixed">
    <origin xyz="0 0.06 0" rpy="0 0 0"/>
    <parent link="camera_link"/>
    <child link="left_camera_frame"/>
  </joint>
  <link name="left_camera_frame"/>

  <joint name="left_camera_optical_joint" type="fixed">
    <origin xyz="0 0 0" rpy="${-M_PI/2} 0 ${-M_PI/2}"/>
    <parent link="left_camera_frame"/>
    <child link="left_camera_optical_frame"/>
  </joint>
  <link name="left_camera_optical_frame"/>

  <joint name="right_camera_joint" type="fixed">
    <origin xyz="0 -0.06 0" rpy="0 0 0"/>
    <parent link="camera_link"/>
    <child link="right_camera_frame"/>
  </joint>
  <link name="right_camera_frame"/>

  <joint name="right_camera_optical_joint" type="fixed">
    <origin xyz="0 0 0" rpy="${-M_PI/2} 0 ${-M_PI/2}"/>
    <parent link="right_camera_frame"/>
    <child link="right_camera_optical_frame"/>
  </joint>
  <link name="right_camera_optical_frame"/>

</robot>
